Workbook

Sheet README
A1: WDPR Fall 2026 IE Case, Autumn Harvest Festival model
A3: How to read this workbook
A4: Blue text = hardcoded input with a source (edit these). Black = formula. Green = link to another sheet. Yellow fill = key assumption.
A5: Every derived number is a live formula that traces back to the Inputs sheet. Change an input and the bridge, weekends, booths and options all move.
A6: Monte Carlo percentiles (P10/P50/P90) are computed by src/festival/simulate.py in the GitHub repo and pasted as values on the Bridge sheet, labeled as such.
A8: Sheet guide
A9: Sources: every research anchor with value, range and URL.
A10: Inputs: the assumption register. Named cells drive every other sheet.
A11: Baseline: five trend methods on 2021 to 2025, holdout backtest, weighted combination, 80% prediction interval.
A12: Capture: attendance divided by ring population for the 500k local ring and the 700k neighboring ring; calibrated model; five-year diffusion path.
A13: Reach: four independent estimates of the new-market lift and their overlap.
A14: Anniversary: milestone comparables and the four bottom-up channels.
... A23: Code: github.com/NathanielKung/disney-festival-ie-case (models, tests, and this workbook's builder).

Sheet Sources
A1: Key | B1: Parameter | C1: Low | D1: Base | E1: High | F1: Unit | G1: Source | H1: URL
A2: ad_elasticity_short | B2: Short-run advertising elasticity | C2: 0.09 | D2: 0.12 | E2: 0.24 | F2: elasticity | G2: Sethuraman, Tellis and Briesch, Journal of Marketing Research 2011 (751 short-run and 402 long-run estimates from 56 studies); 0.09 from a later international meta-analysis | H2: https://journals.sagepub.com/doi/10.1509/jmkr.48.3.457
A3: bass_p | B3: Bass coefficient of innovation p | C3: 0.03 | D3: 0.03 | E3: 0.1 | F3: rate | G3: Sultan, Farley and Lehmann, JMR 1990, meta-analysis of 213 parameter sets; 0.10 reflects heavy advertising in the generalized Bass model | H3: https://proceedings.systemdynamics.org/2015/papers/P1233.pdf
A4: bass_q | B4: Bass coefficient of imitation q | C4: 0.3 | D4: 0.38 | E4: 0.45 | F4: rate | G4: Sultan, Farley and Lehmann, JMR 1990 | H4: https://proceedings.systemdynamics.org/2015/papers/P1233.pdf
A5: campaign_awareness | B5: Campaign awareness in the new ring | C5: 0.15 | D5: 0.25 | E5: 0.35 | F5: share | G5: State tourism ROI studies at higher per-capita spend: Washington 36% (SMARI FY2024), New Mexico 44% (Longwoods 2015), North Dakota 47% | H5: https://industry.stateofwatourism.com/wp-content/uploads/SMARI-2024-for-web.pdf
A6: aware_conversion | B6: Incremental visit rate among aware residents | C6: 0.013 | D6: 0.017 | E6: 0.025 | F6: share | G6: Washington: 77,000 incremental trips from 2.4M aware households (3.2% per household, ~1.3% per resident); Wyoming: likelihood to visit 7% unaware to 14% aware (Longwoods 2019) | H6: https://www.wyoleg.gov/InterimCommittee/2019/02-20191209066-169-WTB2019AdvertisingEffectivenessROI.pdf
A7: outer_share_of_visits | B7: Share of 2025 visits from the neighboring ring | C7: 0.15 | D7: 0.25 | E7: 0.35 | F7: share | G7: Verified visitor-origin surveys: Bolton Food and Drink Festival 72% local postcode; Big Sur Food and Wine 70% Monterey County; promoter claims of 60-80% out-of-region are rarely verified (Stratford Analytics) | H7: https://www.bolton.gov.uk/downloads/file/6971/visitor-report-survey-findings---bolton-food-and-drink-festival-2024
A8: huff_exponent | B8: Huff distance-decay exponent | C8: 1 | D8: 1.5 | E8: 2 | F8: exponent | G8: Esri Huff model documentation: usually ranges between 1.5 and 2 | H8: https://desktop.arcgis.com/en/arcmap/latest/tools/business-analyst-toolbox/how-original-huff-model-works.htm
A9: anniversary_lift | B9: Milestone anniversary lift net of marketing and concert | C9: 0.01 | D9: 0.035 | E9: 0.07 | F9: share | G9: Disneyland 2014-2016 attendance 16.769M / 18.278M / 17.943M (TEA/AECOM); Disneyland 50th +8.5% vs top-50 parks +4.2% (Amusement Business/ERA 2005); Musikfest 40th 1.33M vs prior record 1.24M (Morning Call 2023); Indy 500 100th running sellout (2016) | H9: https://queue-times.com/parks/16/attendances
A10: saturday_share | B10: Saturday share of a weekend | C10: 0.52 | D10: 0.55 | E10: 0.58 | F10: share | G10: Minnesota State Fair first-weekend Saturday vs Sunday: 198,842 vs 171,054 (2022); 198,863 vs 184,176 (2023); 184,564 vs 134,644 (2024) | H10: https://www.mnstatefair.org/about/attendance
A11: weather_multiplier | B11: Season weather multiplier | C11: 0.9 | D11: 1 | E11: 1.02 | F11: multiplier | G11: Minnesota State Fair 2024: one rain day at 81,231 against a normal day near 135,000 (about 40% loss); one washed-out day of eight is 5% of the season | H11: https://www.yahoo.com/news/articles/minnesota-state-fair-attendance-continues-001045059.html
A12: listener_conversion_paid | B12: Paid ticket conversion of metro monthly listeners | C12: 0.01 | D12: 0.02 | E12: 0.03 | F12: share | G12: insights.live: roughly 1% to 3% of an artist's monthly listeners in a metro convert to ticket buyers; Orphiq: 2% working estimate for tour routing | H12: https://insights.live/blog/event-demand-data-you-need-to-forecast-concerts/
A13: listener_conversion_free | B13: Conversion when the show is free with admission | C13: 0.04 | D13: 0.1 | E13: 0.18 | F13: share | G13: Team assumption: five times the paid working estimate because the marginal price of the show is zero | H13: https://orphiq.com/resources/spotify-analytics-tour-routing
... A23: macro_attendance | B23: Net macro multiplier on attendance | C23: -0.02 | D23: -0.004 | E23: 0.015 | F23: share | G23: Derived in macro.py: staycation lift on the local ring, fuel-cost drag on the outer ring, small sentiment drag | H23: https://www.nber.org/papers/w12530

Sheet Inputs
A1: Input | B1: Low | C1: Base | D1: High | E1: Unit | F1: Source / note
A2: Case data
A3: Attendance 2025 | B3: 56000 | C3: 56000 | D3: 56000 | E3: visits | F3: Case
A4: Local ring population | B4: 500000 | C4: 500000 | D4: 500000 | E4: people | F4: Case: local metro
A5: Neighboring ring population | B5: 700000 | C5: 700000 | D5: 700000 | E5: people | F5: Case: 1.2M reach minus 500k
A6: Marketing spend increase | B6: 0.2 | C6: 0.2 | D6: 0.2 | E6: share | F6: Case
A7: Audience multiple (1.2M / 0.5M) | B7: 2.4 | C7: 2.4 | D7: 2.4 | E7: x | F7: Case
A8: Concert capacity | B8: 8000 | C8: 8000 | D8: 8000 | E8: people | F8: Case
A9: Weekend share 1 | B9: 0.2 | C9: 0.2 | D9: 0.2 | E9: share | F9: Case
A10: Weekend share 2 | B10: 0.25 | C10: 0.25 | D10: 0.25 | E10: share | F10: Case
A11: Weekend share 3 | B11: 0.3 | C11: 0.3 | D11: 0.3 | E11: share | F11: Case
A12: Weekend share 4 | B12: 0.25 | C12: 0.25 | D12: 0.25 | E12: share | F12: Case
A13: Part 1 drivers
A14: Organic baseline 2026 | B14: 56800 | C14: =Baseline!C24 -> 58564.75 | D14: 59800 | E14: visits | F14: Base links to the Baseline sheet combination; low/high bracket the five methods
A15: Local marketing spillover | B15: -0.02 | C15: 0.005 | D15: 0.024 | E15: share | F15: Reading A: local budget held. Range from elasticity 0.12 x intensity change
A16: Anniversary lift (net) | B16: 0.01 | C16: 0.035 | D16: 0.07 | E16: share | F16: Sources sheet: anniversary_lift
A17: Macro net attendance effect | B17: -0.02 | C17: =Macro!B24 -> -0.0083611111 | D17: 0.015 | E17: share | F17: Base links to the Macro sheet
A18: Reach expansion lift | B18: 1000 | C18: 2000 | D18: 4500 | E18: visits | F18: Overlap of four methods on the Reach sheet
A19: Concert incremental guests | B19: 400 | C19: 800 | D19: 2000 | E19: visits | F19: Concert sheet, 10M-listener tier; range 5M to 25M
A20: Concert shifted regulars | B20: 100 | C20: 100 | D20: 100 | E20: visits | F20: Concert sheet
A21: Weather multiplier | B21: 0.9 | C21: 1 | D21: 1.02 | E21: x | F21: Sources sheet: weather_multiplier
A22: Saturday share of weekend | B22: 0.52 | C22: 0.55 | D22: 0.58 | E22: share | F22: Sources sheet: saturday_share
A23: Research anchors
A24: Advertising elasticity (short run) | B24: 0.09 | C24: 0.12 | D24: 0.24 | E24: elasticity | F24: Sethuraman, Tellis, Briesch 2011
A25: Bass p (innovation) | B25: 0.03 | C25: 0.03 | D25: 0.1 | E25: rate | F25: Sultan, Farley, Lehmann 1990
A26: Bass q (imitation) | B26: 0.3 | C26: 0.38 | D26: 0.45 | E26: rate | F26: Sultan, Farley, Lehmann 1990
A27: Campaign awareness, new ring | B27: 0.15 | C27: 0.25 | D27: 0.35 | E27: share | F27: State tourism ROI studies (36 to 47% at higher spend)
A28: Conversion among aware | B28: 0.013 | C28: 0.017 | D28: 0.025 | E28: share | F28: Washington 77k trips / 2.4M aware households; Wyoming 7% to 14%
A29: Share of 2025 visits from neighboring ring | B29: 0.15 | C29: 0.25 | D29: 0.35 | E29: share | F29: Verified origin surveys (Bolton 72% local, Big Sur 70%)
A30: Share of visits from beyond both rings | B30: 0.05 | C30: 0.05 | D30: 0.05 | E30: share | F30: Team assumption
A31: Huff distance exponent | B31: 1 | C31: 1.5 | D31: 2 | E31: exponent | F31: Esri Huff model documentation
A32: Distance local (miles) | B32: 12 | C32: 12 | D32: 12 | E32: miles | F32: Team assumption
A33: Distance outer (miles) | B33: 45 | C33: 45 | D33: 45 | E33: miles | F33: Team assumption
A34: Distance weight, outer ring | B34: 0.14 | C34: 0.25 | D34: 0.4 | E34: x | F34: Huff factor at exponent 1.5 to 1.0
A35: Aware-vs-unaware conversion lift | B35: 2 | C35: 2 | D35: 2 | E35: x | F35: Wyoming: 14% vs 7%
... A40: Free event no-show rate | B40: 0.4 | C40: 0.5 | D40: 0.6 | E40: share | F40: VenueSight / Eventbrite
A41: Concert inputs
A42: Spotify monthly listeners (act) | B42: 7400000 | C42: 7400000 | D42: 7400000 | E42: listeners | F42: Placeholder for the booked act; 7.4M Spotify x 1.35 x 0.93 = 9.3M combined, near the 10M tier
A43: Apple / Spotify listener ratio | B43: 0.25 | C43: 0.35 | D43: 0.45 | E43: x | F43: Sources sheet: apple_to_spotify_ratio
A44: Cross-platform overlap | B44: 0.07 | C44: 0.07 | D44: 0.07 | E44: share | F44: Team assumption
...

Sheet Baseline
A1: Historical attendance and trend methods
A2: Year | B2: x (year index) | C2: Attendance | D2: ln(Attendance) | E2: Holt level | F2: Holt trend | G2: Holt 1-step forecast | H2: Note
A3: 2021 | B3: =A3-2020 -> 1 | C3: 49000 | D3: =LN(C3) -> 10.799576 | E3: =C3 -> 49000 | F3: =C4-C3 -> -500 | H3: Case data. Pandemic-suppressed regime.
A4: 2022 | B4: =A4-2020 -> 2 | C4: 48500 | D4: =LN(C4) -> 10.789319 | E4: =$B$11*C4+(1-$B$11)*(E3+F3) -> 48500 | F4: =$B$12*(E4-E3)+(1-$B$12)*F3 -> -500 | G4: =E3+F3 -> 48500 | H4: Case data. Pandemic-suppressed regime.
A5: 2023 | B5: =A5-2020 -> 3 | C5: 50000 | D5: =LN(C5) -> 10.819778 | E5: =$B$11*C5+(1-$B$11)*(E4+F4) -> 49800 | F5: =$B$12*(E5-E4)+(1-$B$12)*F4 -> 1120 | G5: =E4+F4 -> 48000 | H5: Case data. Recovery begins.
A6: 2024 | B6: =A6-2020 -> 4 | C6: 53500 | D6: =LN(C6) -> 10.887437 | E6: =$B$11*C6+(1-$B$11)*(E5+F5) -> 53242 | F6: =$B$12*(E6-E5)+(1-$B$12)*F5 -> 3209.8 | G6: =E5+F5 -> 50920 | H6: Case data.
A7: 2025 | B7: =A7-2020 -> 5 | C7: 56000 | D7: =LN(C7) -> 10.933107 | E7: =$B$11*C7+(1-$B$11)*(E6+F6) -> 56045.18 | F7: =$B$12*(E7-E6)+(1-$B$12)*F6 -> 2843.842 | G7: =E6+F6 -> 56451.8 | H7: Case data. Most recent actual.
A8: 2026 | B8: =A8-2020 -> 6 | G8: =E7+F7 -> 58889.022 | H8: Holt 2026 = last level + last trend
A10: Holt parameters
A11: alpha (level smoothing) | B11: 0.9 | C11: Grid-searched to minimize one-step squared error (baseline.py, holt_optimize). 0.9/0.9 means trust the newest data.
A12: beta (trend smoothing) | B12: 0.9
A14: Five methods for 2026
A15: Method | B15: Formula | C15: 2026 forecast | D15: Weight | E15: Weighted | F15: Holdout miss on 2025 | H15: Read
A16: A. OLS linear, all years | B16: FORECAST(B8,C3:C7,B3:B7) | C16: =FORECAST(B8,C3:C7,B3:B7) -> 57100 | D16: 0.15 | E16: =C16*D16 -> 8565 | F16: =FORECAST(B7,C3:C6,B3:B6)/C7-1 -> -0.035714286 | H16: Constant headcount growth. SLOPE = guests per year.
A17: B. Log-linear, all years | B17: EXP(FORECAST(B8,D3:D7,B3:B7)) | C17: =EXP(FORECAST(B8,D3:D7,B3:B7)) -> 57262.289 | D17: 0.15 | E17: =C17*D17 -> 8589.3434 | F17: =EXP(FORECAST(B7,D3:D6,B3:B6))/C7-1 -> -0.034943551 | H17: Constant percentage growth (CAGR).
A18: C. OLS linear, 2023 to 2025 | B18: FORECAST(B8,C5:C7,B5:B7) | C18: =FORECAST(B8,C5:C7,B5:B7) -> 59166.667 | D18: 0.25 | E18: =C18*D18 -> 14791.667 | F18: =FORECAST(B7,C4:C6,B4:B6)/C7-1 -> -0.005952381 | H18: Post-pandemic regime only (holdout uses the three years before 2025).
A19: D. Log-linear, 2023 to 2025 | B19: EXP(FORECAST(B8,D5:D7,B5:B7)) | C19: =EXP(FORECAST(B8,D5:D7,B5:B7)) -> 59482.42 | D19: 0.2 | E19: =C19*D19 -> 11896.484 | F19: n/a | H19: Recent CAGR.
A20: E. Holt smoothing | B20: G8 | C20: =G8 -> 58889.022 | D20: 0.25 | E20: =C20*D20 -> 14722.255 | F20: n/a | H20: Level plus trend, recent years weighted more.
A22: Slope A (guests per year) | C22: =SLOPE(C3:C7,B3:B7) -> 1900
A23: CAGR B | C23: =EXP(SLOPE(D3:D7,B3:B7))-1 -> 0.03719304
A24: Combined baseline 2026 | C24: =SUM(E16:E20) -> 58564.75
A25: Weights sum | C25: =SUM(D16:D20) -> 1
A27: 80% prediction interval on the linear fit (five points is a short series)
A28: Residual std error | C28: =STEYX(C3:C7,B3:B7) -> 1366.2601
A29: SE of a new observation at x=6 | C29: =C28*SQRT(1+1/5+(B8-AVERAGE(B3:B7))^2/DEVSQ(B3:B7)) -> 1979.899
A30: t (80%, 3 df) | C30: =TINV(0.2,3) -> 1.6377444
A31: Interval low | C31: =C16-C30*C29 -> 53857.432
A32: Interval high | C32: =C16+C30*C29 -> 60342.568
A33: Holdout: hide 2025, forecast it from 2021 to 2024, compare. All misses are negative, so growth is accelerating and recent-regime methods get more weight.
A35: Chart data
A36: Year | B36: Attendance
A37: =A3 -> 2021 | B37: =C3 -> 49000
A38: =A4 -> 2022 | B38: =C4 -> 48500
A39: =A5 -> 2023 | B39: =C5 -> 50000
A40: =A6 -> 2024 | B40: =C6 -> 53500
A41: =A7 -> 2025 | B41: =C7 -> 56000
A42: 2026 base | B42: =C24 -> 58564.75

Sheet Capture
A1: Capture rate = visits from a ring / population of the ring (2025)
A2: Ring | B2: Population | C2: Share of visits | D2: Visits | E2: Capture rate | F2: Note
A3: Local metro (historically advertised) | B3: =PopLocal -> 500000 | C3: =1-OuterShare-BeyondShare -> 0.7 | D3: =Att2025*C3 -> 39200 | E3: =D3/B3 -> 0.0784
A4: Neighboring metros (new reach) | B4: =PopOuter -> 700000 | C4: =OuterShare -> 0.25 | D4: =Att2025*C4 -> 14000 | E4: =D4/B4 -> 0.02
A5: Beyond both rings | C5: =BeyondShare -> 0.05 | D5: =Att2025*C5 -> 2800
A6: Outer / local capture ratio | E6: =E4/E3 -> 0.25510204 | F6: Compare with the Huff distance factor below: distance alone explains most of the gap
A8: Huff gravity check: propensity of an outer-ring resident relative to a local one = (d_outer/d_local)^(-exponent)
A9: Exponent | B9: Distance factor
A10: 1 | B10: =(DistOuter/DistLocal)^(-A10) -> 0.26666667
A11: 1.5 | B11: =(DistOuter/DistLocal)^(-A11) -> 0.13770607
A12: 2 | B12: =(DistOuter/DistLocal)^(-A12) -> 0.071111111
A14: Calibrated model: aware residents convert at AwareLiftX times the unaware rate
A15: Unaware conversion, local | B15: =E3/(AwareLocal*AwareLiftX+(1-AwareLocal)) -> 0.0448 | F15: Backed out of local capture
A16: Aware conversion, local | B16: =B15*AwareLiftX -> 0.0896
A17: Implied distance factor, outer ring | B17: =E4/(AwareOuter*B16+(1-AwareOuter)*B15) -> 0.34340659 | F17: Backed out of outer capture
A18: Outer awareness after campaign | B18: =MIN(1,AwareOuter+AwareGain) -> 0.45
A19: Outer capture after campaign | B19: =(B18*B16+(1-B18)*B15)*B17 -> 0.022307692
A20: Incremental outer visits (year one) | B20: =(B19-E4)*PopOuter -> 1615.3846 | F20: One of the four reach estimates
A21: Outer ceiling capture at full awareness | B21: =B16*B17 -> 0.030769231
A22: Outer ceiling visits | B22: =B21*PopOuter -> 21538.462 | F22: About 7,500 above today
A23: Local ceiling visits at full awareness | B23: =B16*PopLocal -> 44800
A26: Five-year outer-ring path: awareness spreads by a Bass process (p = campaign at BassP_hi, q = word of mouth)
A27: Year | B27: Awareness | C27: Outer capture | D27: Outer visits | E27: vs 2025
A28: 2026 | B28: =MIN(1,AwareOuter+(BassP_hi+BassQ*AwareOuter)*(1-AwareOuter)) -> 0.4498 | C28: =(B28*$B$16+(1-B28)*$B$15)*$B$17 -> 0.022304615 | D28: =C28*PopOuter -> 15613.231 | E28: =D28-$D$4 -> 1613.2308
A29: 2027 | B29: =MIN(1,B28+(BassP_hi+BassQ*B28)*(1-B28)) -> 0.59886238 | C29: =(B29*$B$16+(1-B29)*$B$15)*$B$17 -> 0.024597883 | D29: =C29*PopOuter -> 17218.518 | E29: =D29-$D$4 -> 3218.518
A30: 2028 | B30: =MIN(1,B29+(BassP_hi+BassQ*B29)*(1-B29)) -> 0.73026211 | C30: =(B30*$B$16+(1-B30)*$B$15)*$B$17 -> 0.026619417 | D30: =C30*PopOuter -> 18633.592 | E30: =D30-$D$4 -> 4633.592
A31: 2029 | B31: =MIN(1,B30+(BassP_hi+BassQ*B30)*(1-B30)) -> 0.83208806 | C31: =(B31*$B$16+(1-B31)*$B$15)*$B$17 -> 0.02818597 | D31: =C31*PopOuter -> 19730.179 | E31: =D31-$D$4 -> 5730.1791
A32: 2030 | B32: =MIN(1,B31+(BassP_hi+BassQ*B31)*(1-B31)) -> 0.90197191 | C32: =(B32*$B$16+(1-B32)*$B$15)*$B$17 -> 0.029261106 | D32: =C32*PopOuter -> 20482.774 | E32: =D32-$D$4 -> 6482.7744

Sheet Reach
A1: Marketing arithmetic
A2: Per-capita intensity change if spread evenly | B2: =(1+SpendUp)/AudMult-1 -> -0.5 | D2: Money up 1.2x, audience up 2.4x
A3: Reading B local effect (elasticity x intensity) | B3: =AdElast*B2 -> -0.06 | D3: Spread evenly: local market loses frequency
A4: Reading B local visits | B4: =B3*Att2025 -> -3360
A5: Reading A local spillover (held budget) | B5: =MktLift -> 0.005 | D5: Carried in the bridge
A6: Reading A local visits | B6: =B5*Att2025 -> 280
A8: Four estimates of the new-market lift (visits)
A9: Method | B9: Low | C9: High | D9: How
A10: 1. Elasticity on whole spend increase | B10: =Att2025*SpendUp*AdElast -> 1344 | C10: =Att2025*SpendUp*AdElast_hi -> 2688 | D10: attendance x 20% x elasticity (0.12 short run, 0.24 long run)
A11: 2. Awareness x conversion funnel | B11: =PopOuter*Aware_lo*AwareConv_lo -> 1365 | C11: =PopOuter*Aware*AwareConv -> 2975 | D11: 700k x awareness x conversion
A12: 3. Bass diffusion, year one | B12: =PopOuter*(Att2025/PopLocal)*DistW*BassP -> 588 | C12: =PopOuter*(Att2025/PopLocal)*DistW*BassP_hi -> 1960 | D12: p x market potential; potential = 700k x local rate x distance weight
A13: 4. Calibrated capture model | B13: =Capture!B20*0.6 -> 969.23077 | C13: =Capture!B20*1.67 -> 2697.6923 | D13: Capture sheet, awareness gain 10 to 25 points
A15: Carried in the bridge | B15: =ReachAdd -> 2000 | D15: The overlap of the four ranges. Change ReachAdd on Inputs to override.
A17: Bass market potential (outer ring) | B17: =PopOuter*(Att2025/PopLocal)*DistW -> 19600
A18: Bass path (new adopters per year, p base) | B18: Year 1 | C18: Year 2 | D18: Year 3 | E18: Year 4 | F18: Year 5
A19: Cumulative | B19: =0+B20 -> 588 | C19: =B19+C20 -> 1375.0968 | D19: =C19+D20 -> 2407.7205 | E19: =D19+E20 -> 3726.0296 | F19: =E19+F20 -> 5348.974
A20: New adopters | B20: =(BassP+BassQ*0/$B$17)*($B$17-0) -> 588 | C20: =(BassP+BassQ*B19/$B$17)*($B$17-B19) -> 787.0968 | D20: =(BassP+BassQ*C19/$B$17)*($B$17-C19) -> 1032.6237 | E20: =(BassP+BassQ*D19/$B$17)*($B$17-D19) -> 1318.3091 | F20: =(BassP+BassQ*E19/$B$17)*($B$17-E19) -> 1622.9444

Sheet Anniversary
A1: Top-down: milestone comparables (all-in lift above trend)
A2: Comparable | B2: Prior | C2: Milestone | D2: Lift above trend | E2: Source
A3: Disneyland 60th (2015), trend 3.5% | B3: 16769000 | C3: 18278000 | D3: =C3/B3-1-0.035 -> 0.054987477 | E3: TEA/AECOM Theme Index
A4: Disneyland 50th (2005) vs top-50 parks | B4: 0.042 | C4: 0.085 | D4: =C4-B4 -> 0.043 | E4: Amusement Business / ERA 2005
A5: Musikfest 40th (2023) vs prior record | B5: 1240000 | C5: 1330000 | D5: =C5/B5-1 -> 0.072580645 | E5: Morning Call, Aug 2023
A6: Disneyland 2016 giveback | B6: 18278000 | C6: 17943000 | D6: =C6/B6-1 -> -0.018328045 | E6: Year after the milestone
A7: Pieces counted elsewhere (concert + marketing) | D7: =ConcertAdd/Att2025+MktLift -> 0.019285714
A8: Net milestone lift carried | D8: =AnnivLift -> 0.035
A10: Bottom-up: four channels
A11: Channel | B11: Driver | C11: Visits | D11: % of 2025 | E11: Logic
A12: Lapsed visitors return | B12: =Att2025*(1-RegShare)*10*0.6 -> 67200 | C12: =B12*0.03 -> 2016 | D12: =C12/Att2025 -> 0.036 | E12: Non-regular visits x 10 years x 0.6 movers = pool; 3% reactivate
A13: Earned media | B13: =PopLocal-Att2025*0.7 -> 460800 | C13: =B13*0.2*0.01 -> 921.6 | D13: =C13/Att2025 -> 0.016457143 | E13: Non-attending locals x 20% reached x 1% convert
A14: Special programming | B14: =Att2025 -> 56000 | C14: =B14*0.01 -> 560 | D14: =C14/Att2025 -> 0.01 | E14: 1% attractiveness bump
A15: Regulars add a visit | B15: =Att2025*RegShare*0.3 -> 13440 | C15: =B15*0.02*5 -> 1344 | D15: =C15/Att2025 -> 0.024 | E15: 30% multi-visit regulars, +2% visits, 5 extra visit-days
A16: Stacked | C16: =SUM(C12:C15) -> 4841.6 | D16: =C16/Att2025 -> 0.086457143
A17: Netted for overlap (45%) | C17: =C16*0.55 -> 2662.88 | D17: =C17/Att2025 -> 0.047551429 | E17: A lapsed visitor brought back by a news story is channels 1 and 2 at once

Sheet Concert
A1: Listener funnel for the booked act
A2: Combined monthly listeners | B2: =SpotifyML*(1+AppleRatio)*(1-Overlap) -> 9290700 | D2: Spotify public count + Apple estimate, less overlap
A3: Effective catchment population | B3: =PopLocal+PopOuter*DistW -> 675000 | D3: Outer ring weighted for distance
A4: Catchment listeners | B4: =B2*USShare*(B3/USPop)*Affinity -> 11066.863 | D4: Listeners spread with population, scaled by affinity
A5: Concert-motivated demand | B5: =B4*ConvFree*Engage -> 1106.6863 | D5: Free-show conversion x engagement
A6: Regulars (shift weekends) | B6: =B5*FanRegular*ShowUp -> 77.468043
A7: Incremental guests | B7: =B5*(1-FanRegular)*ShowUp -> 697.21238 | D7: New to the season
A8: Casual on-grounds seat demand | B8: =Weekends!C9*Casual -> 3371.5 | D8: Weekend 4 Saturday guests before the concert
A9: Seat demand | B9: =B8+B6+B7 -> 4146.1804
A10: Overflow above capacity | B10: =MAX(0,B9-ConcertCap) -> 0
A11: Passes to issue if reservation-based | B11: =ConcertCap/(1-NoShow) -> 16000 | D11: Free events lose 40 to 60% of registrants
A13: Act-size tiers (combined listeners)
A14: Combined listeners | B14: Catchment listeners | C14: Incremental guests | D14: Shifted regulars
A15: 1000000 | B15: =A15*USShare*($B$3/USPop)*Affinity -> 1191.1765 | C15: =B15*ConvFree*Engage*(1-FanRegular)*ShowUp -> 75.044118 | D15: =B15*ConvFree*Engage*FanRegular*ShowUp -> 8.3382353
A16: 5000000 | B16: =A16*USShare*($B$3/USPop)*Affinity -> 5955.8824 | C16: =B16*ConvFree*Engage*(1-FanRegular)*ShowUp -> 375.22059 | D16: =B16*ConvFree*Engage*FanRegular*ShowUp -> 41.691176
A17: 10000000 | B17: =A17*USShare*($B$3/USPop)*Affinity -> 11911.765 | C17: =B17*ConvFree*Engage*(1-FanRegular)*ShowUp -> 750.44118 | D17: =B17*ConvFree*Engage*FanRegular*ShowUp -> 83.382353
A18: 20000000 | B18: =A18*USShare*($B$3/USPop)*Affinity -> 23823.529 | C18: =B18*ConvFree*Engage*(1-FanRegular)*ShowUp -> 1500.8824 | D18: =B18*ConvFree*Engage*FanRegular*ShowUp -> 166.76471
A19: 40000000 | B19: =A19*USShare*($B$3/USPop)*Affinity -> 47647.059 | C19: =B19*ConvFree*Engage*(1-FanRegular)*ShowUp -> 3001.7647 | D19: =B19*ConvFree*Engage*FanRegular*ShowUp -> 333.52941
A21: Listeners needed for 2,000 incremental | B21: =2000/C17*A17 -> 26650990
A22: Listeners at which WK4 Sat passes WK3 Sat | B22: =(Weekends!C8-Weekends!C9+ConcertShift)/(C17+D17)*A17 -> 21086596 | D22: Gap between the two Saturdays divided by guests per listener

Sheet Macro
A1: September 2026 readings
A2: Indicator | B2: Now | C2: Year ago | D2: Source
A3: UMich consumer sentiment | B3: 48.1 | C3: 55.1 | D3: University of Michigan Surveys of Consumers, Sept 2026 final vs Sept 2025
A4: One-year inflation expectations | B4: 0.046 | C4: 0.036 | D4: UMich Sept 2026 4.6%; NY Fed Aug 2026 3.6%
A5: Gasoline, national average $/gal | B5: 4.49 | C5: 3.6 | D5: AAA Sept 24-25 2026; about 25% above a year ago (Empower, AAA)
A6: Unemployment rate | B6: 0.041 | C6: 0.042 | D6: BLS via Sept 2026 coverage: 4.1%, payrolls +162k
A7: Retail and food-service sales, y/y nominal | B7: 0.06 | D7: Census, August 2026
A9: Three mechanisms
A10: Gas price change y/y | B10: =GasNow/GasPrior-1 -> 0.24722222 | D10: Input to the fuel-cost mechanism
A11: Extra fuel cost per outer-ring car trip (90 mi, 25 mpg) | B11: =90/25*GasNow-90/25*GasPrior -> 3.204 | D11: A few dollars; the effect is on the margin, not the average
A12: Outer-ring visit effect (trip elasticity x gas change) | B12: =TripElast*B10 -> -0.049444444 | D12: Hughes-Knittel-Sperling: total gasoline demand only -0.03 to -0.08; day trips more elastic
A13: Outer-ring visits effect | B13: =B12*Att2025*OuterShare -> -692.22222
A14: Local staycation lift | B14: =Stay -> 0.01 | D14: 2009: fairs boomed as families skipped out-of-town trips
A15: Local visits effect | B15: =B14*Att2025*(1-OuterShare-BeyondShare) -> 392
A16: Sentiment drag on visits | B16: =SentDrag -> -0.003 | D16: Sentiment near record lows, yet nominal spending +6%
A17: Sentiment visits effect | B17: =B16*Att2025 -> -168
A18: Net attendance effect (visits) | B18: =B13+B15+B17 -> -468.22222
A19: Real per-guest spend change | B19: =PerCap -> -0.04 | D19: Feeds Part 2 sales per booth and Part 3 revenue per guest
A20: Cost escalator for 2027 options | B20: =Escalator -> 0.046 | D20: Feeds Part 3 labor cost
A23: Net macro multiplier on attendance
A24: (local share x staycation + outer share x fuel effect + sentiment) | B24: =(1-OuterShare-BeyondShare)*Stay+OuterShare*B12+SentDrag -> -0.0083611111 | D24: Linked into Inputs!MacroLift and the bridge

Sheet Bridge
A1: Driver bridge: percentages first, headcounts after, weather last
A2: Step | B2: Cumulative | C2: Step size | E2: How
A3: 2025 actual | B3: =Att2025 -> 56000 | E3: Case
A4: + organic trend | B4: =Base2026 -> 58564.75 | C4: =B4-B3 -> 2564.7495 | E4: Baseline sheet, combined
A5: + local marketing spillover | B5: =B4*(1+MktLift) -> 58857.573 | C5: =B5-B4 -> 292.82375 | E5: Reading A
A6: + 25th anniversary | B6: =B5*(1+AnnivLift) -> 60917.588 | C6: =B6-B5 -> 2060.0151 | E6: Net of marketing and concert
A7: + macro backdrop | B7: =B6*(1+MacroLift) -> 60408.25 | C7: =B7-B6 -> -509.33872 | E7: Macro sheet net multiplier
A8: + reach expansion | B8: =B7+ReachAdd -> 62408.25 | C8: =B8-B7 -> 2000 | E8: Reach sheet overlap
A9: + concert | B9: =B8+ConcertAdd -> 63208.25 | C9: =B9-B8 -> 800 | E9: Concert sheet, booked-act tier
A10: Fair-weather total | B10: =B9 -> 63208.25
A11: x weather (base) | B11: =B10*Weather -> 63208.25 | E11: Weather multiplier mode 1.00; downside skewed
A13: Deterministic scenarios (every driver at its low / base / high)
A14: Scenario | B14: Total | C14: vs 2025 | E14: Note
A15: Low (all drivers low) | B15: =(Base2026_lo*(1+MktLift_lo)*(1+AnnivLift_lo)*(1+MacroLift_lo)+ReachAdd_lo+ConcertAdd_lo)*Weather_lo -> 50846.604 | C15: =B15/Att2025-1 -> -0.09202492 | E15: All-adverse: rarely happens together, which is why the Monte Carlo band below is narrower
A16: Base | B16: =(Base2026*(1+MktLift)*(1+AnnivLift)*(1+MacroLift)+ReachAdd+ConcertAdd)*Weather -> 63208.25 | C16: =B16/Att2025-1 -> 0.12871874
A17: High (all drivers high) | B17: =(Base2026_hi*(1+MktLift_hi)*(1+AnnivLift_hi)*(1+MacroLift_hi)+ReachAdd_hi+ConcertAdd_hi)*Weather_hi -> 74464.579 | C17: =B17/Att2025-1 -> 0.32972462
A19: Monte Carlo (simulate.py, 100,000 draws, triangular and PERT distributions), pasted values
A20: Percentile | B20: Total | C20: vs 2025
A21: P10 (low) | B21: 59100 | C21: =B21/Att2025-1 -> 0.055357143
A22: P50 (expected) | B22: 62100 | C22: =B22/Att2025-1 -> 0.10892857
A23: P90 (high) | B23: 64700 | C23: =B23/Att2025-1 -> 0.15535714
A24: P(total > 60,000) | B24: 0.8166

Sheet Sensitivity
A1: Tornado: each driver at its low and high with the others at base (fair-weather total as the anchor)
A2: Driver | B2: Total at low | C2: Total at high | D2: Delta low | E2: Delta high | F2: Swing
A3: Baseline trend | B3: =(Base2026_lo*(1+MktLift)*(1+AnnivLift)*(1+MacroLift)+ReachAdd+ConcertAdd)*Weather -> 61387.949 | C3: =(Base2026_hi*(1+MktLift)*(1+AnnivLift)*(1+MacroLift)+ReachAdd+ConcertAdd)*Weather -> 64482.383 | D3: =B3-Bridge!$B$10 -> -1820.3003 | E3: =C3-Bridge!$B$10 -> 1274.1337 | F3: =ABS(C3-B3) -> 3094.4339
A4: Local marketing | B4: =(Base2026*(1+MktLift_lo)*(1+AnnivLift)*(1+MacroLift)+ReachAdd+ConcertAdd)*Weather -> 61705.557 | C4: =(Base2026*(1+MktLift_hi)*(1+AnnivLift)*(1+MacroLift)+ReachAdd+ConcertAdd)*Weather -> 64350.296 | D4: =B4-Bridge!$B$10 -> -1502.6928 | E4: =C4-Bridge!$B$10 -> 1142.0465 | F4: =ABS(C4-B4) -> 2644.7393
A5: Anniversary | B5: =(Base2026*(1+MktLift)*(1+AnnivLift_lo)*(1+MacroLift)+ReachAdd+ConcertAdd)*Weather -> 61749.113 | C5: =(Base2026*(1+MktLift)*(1+AnnivLift_hi)*(1+MacroLift)+ReachAdd+ConcertAdd)*Weather -> 65251.041 | D5: =B5-Bridge!$B$10 -> -1459.1365 | E5: =C5-Bridge!$B$10 -> 2042.791 | F5: =ABS(C5-B5) -> 3501.9275
A6: Macro | B6: =(Base2026*(1+MktLift)*(1+AnnivLift)*(1+MacroLift_lo)+ReachAdd+ConcertAdd)*Weather -> 62499.237 | C6: =(Base2026*(1+MktLift)*(1+AnnivLift)*(1+MacroLift_hi)+ReachAdd+ConcertAdd)*Weather -> 64631.352 | D6: =B6-Bridge!$B$10 -> -709.01304 | E6: =C6-Bridge!$B$10 -> 1423.1025 | F6: =ABS(C6-B6) -> 2132.1156
A7: Reach | B7: =(Base2026*(1+MktLift)*(1+AnnivLift)*(1+MacroLift)+ReachAdd_lo+ConcertAdd)*Weather -> 62208.25 | C7: =(Base2026*(1+MktLift)*(1+AnnivLift)*(1+MacroLift)+ReachAdd_hi+ConcertAdd)*Weather -> 65708.25 | D7: =B7-Bridge!$B$10 -> -1000 | E7: =C7-Bridge!$B$10 -> 2500 | F7: =ABS(C7-B7) -> 3500
A8: Concert | B8: =(Base2026*(1+MktLift)*(1+AnnivLift)*(1+MacroLift)+ReachAdd+ConcertAdd_lo)*Weather -> 62808.25 | C8: =(Base2026*(1+MktLift)*(1+AnnivLift)*(1+MacroLift)+ReachAdd+ConcertAdd_hi)*Weather -> 64408.25 | D8: =B8-Bridge!$B$10 -> -400 | E8: =C8-Bridge!$B$10 -> 1200 | F8: =ABS(C8-B8) -> 1600
A9: Weather | B9: =(Base2026*(1+MktLift)*(1+AnnivLift)*(1+MacroLift)+ReachAdd+ConcertAdd)*Weather_lo -> 56887.425 | C9: =(Base2026*(1+MktLift)*(1+AnnivLift)*(1+MacroLift)+ReachAdd+ConcertAdd)*Weather_hi -> 64472.415 | D9: =B9-Bridge!$B$10 -> -6320.825 | E9: =C9-Bridge!$B$10 -> 1264.165 | F9: =ABS(C9-B9) -> 7584.99
A11: Full-range swing (low to high). simulate.py reports the 10th-to-90th percentile version; the ranking is the same: weather, then reach and anniversary.

Sheet Weekends
A1: Weekend split anchored on the expected season total (Monte Carlo P50 on the Bridge sheet; switch B1 to Bridge!B10 for the fair-weather deterministic total) | G1: Season total used | H1: =Bridge!B22 -> 62100
A2: Weekend | B2: Share | C2: Weekend total | D2: Saturday | E2: Sunday | F2: Note | G2: Non-concert total | H2: =H1-ConcertAdd*Weather -> 61300
A3: Weekend 1 | B3: =WkS1 -> 0.2 | C3: =$H$2*B3-ConcertShift*0.2 -> 12240 | D3: =C3*SatShare -> 6732 | E3: =C3-D3 -> 5508
A4: Weekend 2 | B4: =WkS2 -> 0.25 | C4: =$H$2*B4-ConcertShift*0.3 -> 15295 | D4: =C4*SatShare -> 8412.25 | E4: =C4-D4 -> 6882.75
A5: Weekend 3 | B5: =WkS3 -> 0.3 | C5: =$H$2*B5-ConcertShift*0.5 -> 18340 | D5: =C5*SatShare -> 10087 | E5: =C5-D5 -> 8253
A6: Weekend 4 | B6: =WkS4 -> 0.25 | C6: =$H$2*B6+ConcertAdd*Weather+ConcertShift -> 16225 | D6: =(C6-ConcertAdd*Weather-ConcertShift)*SatShare+ConcertAdd*Weather+ConcertShift -> 9328.75 | E6: =C6-D6 -> 6896.25 | F6: Concert guests and 100 shifted regulars land on Weekend 4 Saturday
A8: Weekend 3 Saturday (design day) | C8: =D5 -> 10087
A9: Weekend 4 Saturday before the concert | C9: =(C6-ConcertAdd*Weather-ConcertShift)*SatShare -> 8428.75
A10: Weekend 4 Saturday with the concert | C10: =D6 -> 9328.75
A11: Peak day | C11: =IF(D6>D5,"Weekend 4 Saturday","Weekend 3 Saturday") -> Weekend 3 Saturday
A13: Monte Carlo reference (simulate.py, 100,000 draws), pasted values
A14: Weekend | B14: P10 | C14: P50 | D14: P90
A15: Weekend 1 | B15: 11600 | C15: 12200 | D15: 12700
A16: Weekend 2 | B16: 14500 | C16: 15300 | D16: 15900
A17: Weekend 3 | B17: 17400 | C17: 18300 | D17: 19100
A18: Weekend 4 | B18: 15500 | C18: 16300 | D18: 17100
A19: Weekend 3 Saturday | B19: 9600 | C19: 10100 | D19: 10500
A20: Weekend 4 Saturday | B20: 8900 | C20: 9400 | D20: 10000
A21: P(Weekend 4 Saturday is the peak day) | B21: 0.01717

Sheet Part2
A1: Category parameters (case midpoints in blue; service, fees and floors are team assumptions)
A2: Category | B2: Spend $ | C2: Participation | D2: Tx per guest | E2: Units | F2: Season fee $ | G2: Revenue share | H2: Organizer cost $
B3: Vendor floor $ | C3: Service pts | D3: Min per tx | E3: Guests/hr per booth | F3: Peak-hour factor | G3: Wait target (min)
A4: F&B | B4: 21.5 | C4: 0.775 | D4: 1.6 | E4: 1 | F4: 2000 | G4: 0.12 | H4: 900
B5: 18000 | C5: 2 | D5: 2.5 | E5: =60/D5*C5 -> 48 | F5: 0.18 | G5: 10
A6: Merch | B6: 16 | C6: 0.325 | D6: 1.1 | E6: 1 | F6: 900 | G6: 0.1 | H6: 500
B7: 5000 | C7: 1 | D7: 3 | E7: =60/D7*C7 -> 20 | F7: 0.15 | G7: 5
A8: A&E | B8: 8.5 | C8: 0.4 | D8: 1.3 | E8: 2 | F8: 700 | G8: 0.08 | H8: 600
B9: 4000 | C9: attraction | E9: 60 | F9: 0.15 | G9: 15
A10: Season attendance (P50) | B10: =Bridge!B22 -> 62100
A11: Design day (Weekend 3 Saturday) | B11: =Weekends!C8 -> 10087
A12: Real per-guest spend multiplier | B12: =1+PerCap -> 0.96
A14: Design-day demand and Erlang C queue floors
A15: Category | B15: Daily transactions | C15: Peak-hour arrivals (lambda) | D15: Service rate per booth (mu) | E15: Offered load a = lambda/mu | F15: Queue floor (booths) | G15: Wait at floor (min) | H15: Season sales potential $
A16: F&B | B16: =$B$11*C4*D4 -> 12507.88 | C16: =B16*F5 -> 2251.4184 | D16: =E5 -> 48 | E16: =C16/D16 -> 46.90455 | F16: =MIN(ErlangC!B$3:B$102) -> 48 | G16: =INDEX(ErlangC!C$3:C$102,MATCH(F16,ErlangC!$A$3:$A$102,0)) -> 0.9362095 | H16: =$B$10*C4*D4*B4*$B$12 -> 1589362.6
A17: Merch | B17: =$B$11*C6*D6 -> 3606.1025 | C17: =B17*F7 -> 540.91538 | D17: =E7 -> 20 | E17: =C17/D17 -> 27.045769 | F17: =MIN(ErlangC!E$3:E$102) -> 28 | G17: =INDEX(ErlangC!F$3:F$102,MATCH(F17,ErlangC!$A$3:$A$102,0)) -> 2.510375 | H17: =$B$10*C6*D6*B6*$B$12 -> 341003.52
A18: A&E | B18: =$B$11*C8*D8 -> 5245.24 | C18: =B18*F9 -> 786.786 | D18: =E9 -> 60 | E18: =C18/D18 -> 13.1131 | F18: =MIN(ErlangC!H$3:H$102) -> 14 | G18: =INDEX(ErlangC!I$3:I$102,MATCH(F18,ErlangC!$A$3:$A$102,0)) -> 0.83827212 | H18: =$B$10*C8*D8*B8*$B$12 -> 263502.72
A20: Candidate mixes (capture = 1 - EXP(-n / n0), n0 set so capture = 85% at the queue floor)
A21: Mix | B21: F&B booths | C21: Merch booths | D21: A&E booths | E21: Units used | F21: Organizer contribution $ | H21: Check
A22: Profit max (grid search, booths.py) | B22: 64 | C22: 28 | D22: 14 | E22: =B22+C22+2*D22 -> 120 | F22: =F29+F30+F31 -> 305426.44 | H22: =IF(E22<=120,"fits 120 units","over budget") -> fits 120 units
A23: Balanced (recommended) | B23: 60 | C23: 28 | D23: 16 | E23: =B23+C23+2*D23 -> 120 | F23: =F33+F34+F35 -> 299373.62 | H23: =IF(E23<=120,"fits 120 units","over budget") -> fits 120 units
A24: Variety | B24: 56 | C24: 32 | D24: 16 | E24: =B24+C24+2*D24 -> 120 | F24: =F37+F38+F39 -> 294738.52 | H24: =IF(E24<=120,"fits 120 units","over budget") -> fits 120 units
A27: Mix detail
A28: Mix / category | B28: Booths | C28: Capture | D28: Season sales $ | E28: Sales per booth $ | F28: Contribution $ | G28: Peak wait (min) | H28: Above vendor floor?
A29: Profit max / F&B | B29: =B22 -> 64 | C29: =1-EXP(-B29/(F16/-LN(1-0.85))) -> 0.92030061 | D29: =H16*C29 -> 1462691.3 | E29: =D29/B29 -> 22854.552 | F29: =F4*B29+G4*D29-H4*B29 -> 245922.96 | G29: =IFERROR(INDEX(ErlangC!C$3:C$102,MATCH(B29,ErlangC!$A$3:$A$102,0)),0) -> 0.00083316833 | H29: =IF(E29>=B5,"yes","NO") -> yes
A30: Profit max / Merch | B30: =C22 -> 28 | C30: =1-EXP(-B30/(F17/-LN(1-0.85))) -> 0.85 | D30: =H17*C30 -> 289852.99 | E30: =D30/B30 -> 10351.893 | F30: =F6*B30+G6*D30-H6*B30 -> 40185.299 | G30: =IFERROR(INDEX(ErlangC!F$3:F$102,MATCH(B30,ErlangC!$A$3:$A$102,0)),0) -> 2.510375 | H30: =IF(E30>=B7,"yes","NO") -> yes
A31: Profit max / A&E | B31: =D22 -> 14 | C31: =1-EXP(-B31/(F18/-LN(1-0.85))) -> 0.85 | D31: =H18*C31 -> 223977.31 | E31: =D31/B31 -> 15998.379 | F31: =F8*B31+G8*D31-H8*B31 -> 19318.185 | G31: =IFERROR(INDEX(ErlangC!I$3:I$102,MATCH(B31,ErlangC!$A$3:$A$102,0)),0) -> 0.83827212 | H31: =IF(E31>=B9,"yes","NO") -> yes
A33: Balanced / F&B | B33: =B23 -> 60 | C33: =1-EXP(-B33/(F16/-LN(1-0.85))) -> 0.90665005 | D33: =H16*C33 -> 1440995.6 | E33: =D33/B33 -> 24016.594 | F33: =F4*B33+G4*D33-H4*B33 -> 238919.48 | G33: =IFERROR(INDEX(ErlangC!C$3:C$102,MATCH(B33,ErlangC!$A$3:$A$102,0)),0) -> 0.0041694092 | H33: =IF(E33>=B5,"yes","NO") -> yes
A34: Balanced / Merch | B34: =C23 -> 28 | C34: =1-EXP(-B34/(F17/-LN(1-0.85))) -> 0.85 | D34: =H17*C34 -> 289852.99 | E34: =D34/B34 -> 10351.893 | F34: =F6*B34+G6*D34-H6*B34 -> 40185.299 | G34: =IFERROR(INDEX(ErlangC!F$3:F$102,MATCH(B34,ErlangC!$A$3:$A$102,0)),0) -> 2.510375 | H34: =IF(E34>=B7,"yes","NO") -> yes
A35: Balanced / A&E | B35: =D23 -> 16 | C35: =1-EXP(-B35/(F18/-LN(1-0.85))) -> 0.88560949 | D35: =H18*C35 -> 233360.51 | E35: =D35/B35 -> 14585.032 | F35: =F8*B35+G8*D35-H8*B35 -> 20268.841 | G35: =IFERROR(INDEX(ErlangC!I$3:I$102,MATCH(B35,ErlangC!$A$3:$A$102,0)),0) -> 0.12181156 | H35: =IF(E35>=B9,"yes","NO") -> yes
A37: Variety / F&B | B37: =B24 -> 56 | C37: =1-EXP(-B37/(F16/-LN(1-0.85))) -> 0.89066149 | D37: =H16*C37 -> 1415584 | E37: =D37/B37 -> 25278.286 | F37: =F4*B37+G4*D37-H4*B37 -> 231470.08 | G37: =IFERROR(INDEX(ErlangC!C$3:C$102,MATCH(B37,ErlangC!$A$3:$A$102,0)),0) -> 0.01896117 | H37: =IF(E37>=B5,"yes","NO") -> yes
A38: Variety / Merch | B38: =C24 -> 32 | C38: =1-EXP(-B38/(F17/-LN(1-0.85))) -> 0.88560949 | D38: =H17*C38 -> 301995.95 | E38: =D38/B38 -> 9437.3735 | F38: =F6*B38+G6*D38-H6*B38 -> 42999.595 | G38: =IFERROR(INDEX(ErlangC!F$3:F$102,MATCH(B38,ErlangC!$A$3:$A$102,0)),0) -> 0.1625636 | H38: =IF(E38>=B7,"yes","NO") -> yes
A39: Variety / A&E | B39: =D24 -> 16 | C39: =1-EXP(-B39/(F18/-LN(1-0.85))) -> 0.88560949 | D39: =H18*C39 -> 233360.51 | E39: =D39/B39 -> 14585.032 | F39: =F8*B39+G8*D39-H8*B39 -> 20268.841 | G39: =IFERROR(INDEX(ErlangC!I$3:I$102,MATCH(B39,ErlangC!$A$3:$A$102,0)),0) -> 0.12181156 | H39: =IF(E39>=B9,"yes","NO") -> yes

Sheet ErlangC
A1: Erlang C (M/M/c): mean queue wait in minutes for c booths. Helper for Part2. Column pairs: floor flag, wait.
A2: c (booths) | B2: F&B floor? | C2: F&B wait | D2: F&B P(wait) | E2: Merch floor? | F2: Merch wait | G2: Merch P(wait) | H2: A&E floor? | I2: A&E wait | J2: A&E P(wait) | L2: k
A3: 1 | B3: =IF(C3<=Part2!$G$5,A3,9999) -> 9999 | C3: =IF(A3<=(Part2!$C$16/Part2!$D$16),9999,D3/(A3*Part2!$D$16-Part2!$C$16)*60) -> 9999 | D3: =IF(A3<=(Part2!$C$16/Part2!$D$16),1,((Part2!$C$16/Part2!$D$16)^A3/FACT(A3)*A3/(A3-(Part2!$C$16/Part2!$D$16)))/(SUMPRODUCT(($L$3:$L$102<A3)*((Part2!$C$16/Part2!$D$16)^$L$3:$L$102/FACT($L$3:$L$102)))+((Part2!$C$16/Part2!$D$16)^A3/FACT(A3)*A3/(A3-(Part2!$C$16/Part2!$D$16))))) -> 1 | E3: =IF(F3<=Part2!$G$7,A3,9999) -> 9999 | F3: =IF(A3<=(Part2!$C$17/Part2!$D$17),9999,G3/(A3*Part2!$D$17-Part2!$C$17)*60) -> 9999 | G3: =IF(A3<=(Part2!$C$17/Part2!$D$17),1,((Part2!$C$17/Part2!$D$17)^A3/FACT(A3)*A3/(A3-(Part2!$C$17/Part2!$D$17)))/(SUMPRODUCT(($L$3:$L$102<A3)*((Part2!$C$17/Part2!$D$17)^$L$3:$L$102/FACT($L$3:$L$102)))+((Part2!$C$17/Part2!$D$17)^A3/FACT(A3)*A3/(A3-(Part2!$C$17/Part2!$D$17))))) -> 1 | H3: =IF(I3<=Part2!$G$9,A3,9999) -> 9999 | I3: =IF(A3<=(Part2!$C$18/Part2!$D$18),9999,J3/(A3*Part2!$D$18-Part2!$C$18)*60) -> 9999 | J3: =IF(A3<=(Part2!$C$18/Part2!$D$18),1,((Part2!$C$18/Part2!$D$18)^A3/FACT(A3)*A3/(A3-(Part2!$C$18/Part2!$D$18)))/(SUMPRODUCT(($L$3:$L$102<A3)*((Part2!$C$18/Part2!$D$18)^$L$3:$L$102/FACT($L$3:$L$102)))+((Part2!$C$18/Part2!$D$18)^A3/FACT(A3)*A3/(A3-(Part2!$C$18/Part2!$D$18))))) -> 1 | L3: 0
A4: 2 | B4: =IF(C4<=Part2!$G$5,A4,9999) -> 9999 | C4: =IF(A4<=(Part2!$C$16/Part2!$D$16),9999,D4/(A4*Part2!$D$16-Part2!$C$16)*60) -> 9999 | D4: =IF(A4<=(Part2!$C$16/Part2!$D$16),1,((Part2!$C$16/Part2!$D$16)^A4/FACT(A4)*A4/(A4-(Part2!$C$16/Part2!$D$16)))/(SUMPRODUCT(($L$3:$L$102<A4)*((Part2!$C$16/Part2!$D$16)^$L$3:$L$102/FACT($L$3:$L$102)))+((Part2!$C$16/Part2!$D$16)^A4/FACT(A4)*A4/(A4-(Part2!$C$16/Part2!$D$16))))) -> 1 | E4: =IF(F4<=Part2!$G$7,A4,9999) -> 9999 | F4: =IF(A4<=(Part2!$C$17/Part2!$D$17),9999,G4/(A4*Part2!$D$17-Part2!$C$17)*60) -> 9999 | G4: =IF(A4<=(Part2!$C$17/Part2!$D$17),1,((Part2!$C$17/Part2!$D$17)^A4/FACT(A4)*A4/(A4-(Part2!$C$17/Part2!$D$17)))/(SUMPRODUCT(($L$3:$L$102<A4)*((Part2!$C$17/Part2!$D$17)^$L$3:$L$102/FACT($L$3:$L$102)))+((Part2!$C$17/Part2!$D$17)^A4/FACT(A4)*A4/(A4-(Part2!$C$17/Part2!$D$17))))) -> 1 | H4: =IF(I4<=Part2!$G$9,A4,9999) -> 9999 | I4: =IF(A4<=(Part2!$C$18/Part2!$D$18),9999,J4/(A4*Part2!$D$18-Part2!$C$18)*60) -> 9999 | J4: =IF(A4<=(Part2!$C$18/Part2!$D$18),1,((Part2!$C$18/Part2!$D$18)^A4/FACT(A4)*A4/(A4-(Part2!$C$18/Part2!$D$18)))/(SUMPRODUCT(($L$3:$L$102<A4)*((Part2!$C$18/Part2!$D$18)^$L$3:$L$102/FACT($L$3:$L$102)))+((Part2!$C$18/Part2!$D$18)^A4/FACT(A4)*A4/(A4-(Part2!$C$18/Part2!$D$18))))) -> 1 | L4: 1
A5: 3 | B5: =IF(C5<=Part2!$G$5,A5,9999) -> 9999 | C5: =IF(A5<=(Part2!$C$16/Part2!$D$16),9999,D5/(A5*Part2!$D$16-Part2!$C$16)*60) -> 9999 | D5: =IF(A5<=(Part2!$C$16/Part2!$D$16),1,((Part2!$C$16/Part2!$D$16)^A5/FACT(A5)*A5/(A5-(Part2!$C$16/Part2!$D$16)))/(SUMPRODUCT(($L$3:$L$102<A5)*((Part2!$C$16/Part2!$D$16)^$L$3:$L$102/FACT($L$3:$L$102)))+((Part2!$C$16/Part2!$D$16)^A5/FACT(A5)*A5/(A5-(Part2!$C$16/Part2!$D$16))))) -> 1 | E5: =IF(F5<=Part2!$G$7,A5,9999) -> 9999 | F5: =IF(A5<=(Part2!$C$17/Part2!$D$17),9999,G5/(A5*Part2!$D$17-Part2!$C$17)*60) -> 9999 | G5: =IF(A5<=(Part2!$C$17/Part2!$D$17),1,((Part2!$C$17/Part2!$D$17)^A5/FACT(A5)*A5/(A5-(Part2!$C$17/Part2!$D$17)))/(SUMPRODUCT(($L$3:$L$102<A5)*((Part2!$C$17/Part2!$D$17)^$L$3:$L$102/FACT($L$3:$L$102)))+((Part2!$C$17/Part2!$D$17)^A5/FACT(A5)*A5/(A5-(Part2!$C$17/Part2!$D$17))))) -> 1 | H5: =IF(I5<=Part2!$G$9,A5,9999) -> 9999 | I5: =IF(A5<=(Part2!$C$18/Part2!$D$18),9999,J5/(A5*Part2!$D$18-Part2!$C$18)*60) -> 9999 | J5: =IF(A5<=(Part2!$C$18/Part2!$D$18),1,((Part2!$C$18/Part2!$D$18)^A5/FACT(A5)*A5/(A5-(Part2!$C$18/Part2!$D$18)))/(SUMPRODUCT(($L$3:$L$102<A5)*((Part2!$C$18/Part2!$D$18)^$L$3:$L$102/FACT($L$3:$L$102)))+((Part2!$C$18/Part2!$D$18)^A5/FACT(A5)*A5/(A5-(Part2!$C$18/Part2!$D$18))))) -> 1 | L5: 2
A6: 4 | B6: =IF(C6<=Part2!$G$5,A6,9999) -> 9999 | C6: =IF(A6<=(Part2!$C$16/Part2!$D$16),9999,D6/(A6*Part2!$D$16-Part2!$C$16)*60) -> 9999 | D6: =IF(A6<=(Part2!$C$16/Part2!$D$16),1,((Part2!$C$16/Part2!$D$16)^A6/FACT(A6)*A6/(A6-(Part2!$C$16/Part2!$D$16)))/(SUMPRODUCT(($L$3:$L$102<A6)*((Part2!$C$16/Part2!$D$16)^$L$3:$L$102/FACT($L$3:$L$102)))+((Part2!$C$16/Part2!$D$16)^A6/FACT(A6)*A6/(A6-(Part2!$C$16/Part2!$D$16))))) -> 1 | E6: =IF(F6<=Part2!$G$7,A6,9999) -> 9999 | F6: =IF(A6<=(Part2!$C$17/Part2!$D$17),9999,G6/(A6*Part2!$D$17-Part2!$C$17)*60) -> 9999 | G6: =IF(A6<=(Part2!$C$17/Part2!$D$17),1,((Part2!$C$17/Part2!$D$17)^A6/FACT(A6)*A6/(A6-(Part2!$C$17/Part2!$D$17)))/(SUMPRODUCT(($L$3:$L$102<A6)*((Part2!$C$17/Part2!$D$17)^$L$3:$L$102/FACT($L$3:$L$102)))+((Part2!$C$17/Part2!$D$17)^A6/FACT(A6)*A6/(A6-(Part2!$C$17/Part2!$D$17))))) -> 1 | H6: =IF(I6<=Part2!$G$9,A6,9999) -> 9999 | I6: =IF(A6<=(Part2!$C$18/Part2!$D$18),9999,J6/(A6*Part2!$D$18-Part2!$C$18)*60) -> 9999 | J6: =IF(A6<=(Part2!$C$18/Part2!$D$18),1,((Part2!$C$18/Part2!$D$18)^A6/FACT(A6)*A6/(A6-(Part2!$C$18/Part2!$D$18)))/(SUMPRODUCT(($L$3:$L$102<A6)*((Part2!$C$18/Part2!$D$18)^$L$3:$L$102/FACT($L$3:$L$102)))+((Part2!$C$18/Part2!$D$18)^A6/FACT(A6)*A6/(A6-(Part2!$C$18/Part2!$D$18))))) -> 1 | L6: 3
A7: 5 | B7: =IF(C7<=Part2!$G$5,A7,9999) -> 9999 | C7: =IF(A7<=(Part2!$C$16/Part2!$D$16),9999,D7/(A7*Part2!$D$16-Part2!$C$16)*60) -> 9999 | D7: =IF(A7<=(Part2!$C$16/Part2!$D$16),1,((Part2!$C$16/Part2!$D$16)^A7/FACT(A7)*A7/(A7-(Part2!$C$16/Part2!$D$16)))/(SUMPRODUCT(($L$3:$L$102<A7)*((Part2!$C$16/Part2!$D$16)^$L$3:$L$102/FACT($L$3:$L$102)))+((Part2!$C$16/Part2!$D$16)^A7/FACT(A7)*A7/(A7-(Part2!$C$16/Part2!$D$16))))) -> 1 | E7: =IF(F7<=Part2!$G$7,A7,9999) -> 9999 | F7: =IF(A7<=(Part2!$C$17/Part2!$D$17),9999,G7/(A7*Part2!$D$17-Part2!$C$17)*60) -> 9999 | G7: =IF(A7<=(Part2!$C$17/Part2!$D$17),1,((Part2!$C$17/Part2!$D$17)^A7/FACT(A7)*A7/(A7-(Part2!$C$17/Part2!$D$17)))/(SUMPRODUCT(($L$3:$L$102<A7)*((Part2!$C$17/Part2!$D$17)^$L$3:$L$102/FACT($L$3:$L$102)))+((Part2!$C$17/Part2!$D$17)^A7/FACT(A7)*A7/(A7-(Part2!$C$17/Part2!$D$17))))) -> 1 | H7: =IF(I7<=Part2!$G$9,A7,9999) -> 9999 | I7: =IF(A7<=(Part2!$C$18/Part2!$D$18),9999,J7/(A7*Part2!$D$18-Part2!$C$18)*60) -> 9999 | J7: =IF(A7<=(Part2!$C$18/Part2!$D$18),1,((Part2!$C$18/Part2!$D$18)^A7/FACT(A7)*A7/(A7-(Part2!$C$18/Part2!$D$18)))/(SUMPRODUCT(($L$3:$L$102<A7)*((Part2!$C$18/Part2!$D$18)^$L$3:$L$102/FACT($L$3:$L$102)))+((Part2!$C$18/Part2!$D$18)^A7/FACT(A7)*A7/(A7-(Part2!$C$18/Part2!$D$18))))) -> 1 | L7: 4
A8: 6 | B8: =IF(C8<=Part2!$G$5,A8,9999) -> 9999 | C8: =IF(A8<=(Part2!$C$16/Part2!$D$16),9999,D8/(A8*Part2!$D$16-Part2!$C$16)*60) -> 9999 | D8: =IF(A8<=(Part2!$C$16/Part2!$D$16),1,((Part2!$C$16/Part2!$D$16)^A8/FACT(A8)*A8/(A8-(Part2!$C$16/Part2!$D$16)))/(SUMPRODUCT(($L$3:$L$102<A8)*((Part2!$C$16/Part2!$D$16)^$L$3:$L$102/FACT($L$3:$L$102)))+((Part2!$C$16/Part2!$D$16)^A8/FACT(A8)*A8/(A8-(Part2!$C$16/Part2!$D$16))))) -> 1 | E8: =IF(F8<=Part2!$G$7,A8,9999) -> 9999 | F8: =IF(A8<=(Part2!$C$17/Part2!$D$17),9999,G8/(A8*Part2!$D$17-Part2!$C$17)*60) -> 9999 | G8: =IF(A8<=(Part2!$C$17/Part2!$D$17),1,((Part2!$C$17/Part2!$D$17)^A8/FACT(A8)*A8/(A8-(Part2!$C$17/Part2!$D$17)))/(SUMPRODUCT(($L$3:$L$102<A8)*((Part2!$C$17/Part2!$D$17)^$L$3:$L$102/FACT($L$3:$L$102)))+((Part2!$C$17/Part2!$D$17)^A8/FACT(A8)*A8/(A8-(Part2!$C$17/Part2!$D$17))))) -> 1 | H8: =IF(I8<=Part2!$G$9,A8,9999) -> 9999 | I8: =IF(A8<=(Part2!$C$18/Part2!$D$18),9999,J8/(A8*Part2!$D$18-Part2!$C$18)*60) -> 9999 | J8: =IF(A8<=(Part2!$C$18/Part2!$D$18),1,((Part2!$C$18/Part2!$D$18)^A8/FACT(A8)*A8/(A8-(Part2!$C$18/Part2!$D$18)))/(SUMPRODUCT(($L$3:$L$102<A8)*((Part2!$C$18/Part2!$D$18)^$L$3:$L$102/FACT($L$3:$L$102)))+((Part2!$C$18/Part2!$D$18)^A8/FACT(A8)*A8/(A8-(Part2!$C$18/Part2!$D$18))))) -> 1 | L8: 5
A9: 7 | B9: =IF(C9<=Part2!$G$5,A9,9999) -> 9999 | C9: =IF(A9<=(Part2!$C$16/Part2!$D$16),9999,D9/(A9*Part2!$D$16-Part2!$C$16)*60) -> 9999 | D9: =IF(A9<=(Part2!$C$16/Part2!$D$16),1,((Part2!$C$16/Part2!$D$16)^A9/FACT(A9)*A9/(A9-(Part2!$C$16/Part2!$D$16)))/(SUMPRODUCT(($L$3:$L$102<A9)*((Part2!$C$16/Part2!$D$16)^$L$3:$L$102/FACT($L$3:$L$102)))+((Part2!$C$16/Part2!$D$16)^A9/FACT(A9)*A9/(A9-(Part2!$C$16/Part2!$D$16))))) -> 1 | E9: =IF(F9<=Part2!$G$7,A9,9999) -> 9999 | F9: =IF(A9<=(Part2!$C$17/Part2!$D$17),9999,G9/(A9*Part2!$D$17-Part2!$C$17)*60) -> 9999 | G9: =IF(A9<=(Part2!$C$17/Part2!$D$17),1,((Part2!$C$17/Part2!$D$17)^A9/FACT(A9)*A9/(A9-(Part2!$C$17/Part2!$D$17)))/(SUMPRODUCT(($L$3:$L$102<A9)*((Part2!$C$17/Part2!$D$17)^$L$3:$L$102/FACT($L$3:$L$102)))+((Part2!$C$17/Part2!$D$17)^A9/FACT(A9)*A9/(A9-(Part2!$C$17/Part2!$D$17))))) -> 1 | H9: =IF(I9<=Part2!$G$9,A9,9999) -> 9999 | I9: =IF(A9<=(Part2!$C$18/Part2!$D$18),9999,J9/(A9*Part2!$D$18-Part2!$C$18)*60) -> 9999 | J9: =IF(A9<=(Part2!$C$18/Part2!$D$18),1,((Part2!$C$18/Part2!$D$18)^A9/FACT(A9)*A9/(A9-(Part2!$C$18/Part2!$D$18)))/(SUMPRODUCT(($L$3:$L$102<A9)*((Part2!$C$18/Part2!$D$18)^$L$3:$L$102/FACT($L$3:$L$102)))+((Part2!$C$18/Part2!$D$18)^A9/FACT(A9)*A9/(A9-(Part2!$C$18/Part2!$D$18))))) -> 1 | L9: 6
A10: 8 | B10: =IF(C10<=Part2!$G$5,A10,9999) -> 9999 | C10: =IF(A10<=(Part2!$C$16/Part2!$D$16),9999,D10/(A10*Part2!$D$16-Part2!$C$16)*60) -> 9999 | D10: =IF(A10<=(Part2!$C$16/Part2!$D$16),1,((Part2!$C$16/Part2!$D$16)^A10/FACT(A10)*A10/(A10-(Part2!$C$16/Part2!$D$16)))/(SUMPRODUCT(($L$3:$L$102<A10)*((Part2!$C$16/Part2!$D$16)^$L$3:$L$102/FACT($L$3:$L$102)))+((Part2!$C$16/Part2!$D$16)^A10/FACT(A10)*A10/(A10-(Part2!$C$16/Part2!$D$16))))) -> 1 | E10: =IF(F10<=Part2!$G$7,A10,9999) -> 9999 | F10: =IF(A10<=(Part2!$C$17/Part2!$D$17),9999,G10/(A10*Part2!$D$17-Part2!$C$17)*60) -> 9999 | G10: =IF(A10<=(Part2!$C$17/Part2!$D$17),1,((Part2!$C$17/Part2!$D$17)^A10/FACT(A10)*A10/(A10-(Part2!$C$17/Part2!$D$17)))/(SUMPRODUCT(($L$3:$L$102<A10)*((Part2!$C$17/Part2!$D$17)^$L$3:$L$102/FACT($L$3:$L$102)))+((Part2!$C$17/Part2!$D$17)^A10/FACT(A10)*A10/(A10-(Part2!$C$17/Part2!$D$17))))) -> 1 | H10: =IF(I10<=Part2!$G$9,A10,9999) -> 9999 | I10: =IF(A10<=(Part2!$C$18/Part2!$D$18),9999,J10/(A10*Part2!$D$18-Part2!$C$18)*60) -> 9999 | J10: =IF(A10<=(Part2!$C$18/Part2!$D$18),1,((Part2!$C$18/Part2!$D$18)^A10/FACT(A10)*A10/(A10-(Part2!$C$18/Part2!$D$18)))/(SUMPRODUCT(($L$3:$L$102<A10)*((Part2!$C$18/Part2!$D$18)^$L$3:$L$102/FACT($L$3:$L$102)))+((Part2!$C$18/Part2!$D$18)^A10/FACT(A10)*A10/(A10-(Part2!$C$18/Part2!$D$18))))) -> 1 | L10: 7
A11: 9 | B11: =IF(C11<=Part2!$G$5,A11,9999) -> 9999 | C11: =IF(A11<=(Part2!$C$16/Part2!$D$16),9999,D11/(A11*Part2!$D$16-Part2!$C$16)*60) -> 9999 | D11: =IF(A11<=(Part2!$C$16/Part2!$D$16),1,((Part2!$C$16/Part2!$D$16)^A11/FACT(A11)*A11/(A11-(Part2!$C$16/Part2!$D$16)))/(SUMPRODUCT(($L$3:$L$102<A11)*((Part2!$C$16/Part2!$D$16)^$L$3:$L$102/FACT($L$3:$L$102)))+((Part2!$C$16/Part2!$D$16)^A11/FACT(A11)*A11/(A11-(Part2!$C$16/Part2!$D$16))))) -> 1 | E11: =IF(F11<=Part2!$G$7,A11,9999) -> 9999 | F11: =IF(A11<=(Part2!$C$17/Part2!$D$17),9999,G11/(A11*Part2!$D$17-Part2!$C$17)*60) -> 9999 | G11: =IF(A11<=(Part2!$C$17/Part2!$D$17),1,((Part2!$C$17/Part2!$D$17)^A11/FACT(A11)*A11/(A11-(Part2!$C$17/Part2!$D$17)))/(SUMPRODUCT(($L$3:$L$102<A11)*((Part2!$C$17/Part2!$D$17)^$L$3:$L$102/FACT($L$3:$L$102)))+((Part2!$C$17/Part2!$D$17)^A11/FACT(A11)*A11/(A11-(Part2!$C$17/Part2!$D$17))))) -> 1 | H11: =IF(I11<=Part2!$G$9,A11,9999) -> 9999 | I11: =IF(A11<=(Part2!$C$18/Part2!$D$18),9999,J11/(A11*Part2!$D$18-Part2!$C$18)*60) -> 9999 | J11: =IF(A11<=(Part2!$C$18/Part2!$D$18),1,((Part2!$C$18/Part2!$D$18)^A11/FACT(A11)*A11/(A11-(Part2!$C$18/Part2!$D$18)))/(SUMPRODUCT(($L$3:$L$102<A11)*((Part2!$C$18/Part2!$D$18)^$L$3:$L$102/FACT($L$3:$L$102)))+((Part2!$C$18/Part2!$D$18)^A11/FACT(A11)*A11/(A11-(Part2!$C$18/Part2!$D$18))))) -> 1 | L11: 8
A12: 10 | B12: =IF(C12<=Part2!$G$5,A12,9999) -> 9999 | C12: =IF(A12<=(Part2!$C$16/Part2!$D$16),9999,D12/(A12*Part2!$D$16-Part2!$C$16)*60) -> 9999 | D12: =IF(A12<=(Part2!$C$16/Part2!$D$16),1,((Part2!$C$16/Part2!$D$16)^A12/FACT(A12)*A12/(A12-(Part2!$C$16/Part2!$D$16)))/(SUMPRODUCT(($L$3:$L$102<A12)*((Part2!$C$16/Part2!$D$16)^$L$3:$L$102/FACT($L$3:$L$102)))+((Part2!$C$16/Part2!$D$16)^A12/FACT(A12)*A12/(A12-(Part2!$C$16/Part2!$D$16))))) -> 1 | E12: =IF(F12<=Part2!$G$7,A12,9999) -> 9999 | F12: =IF(A12<=(Part2!$C$17/Part2!$D$17),9999,G12/(A12*Part2!$D$17-Part2!$C$17)*60) -> 9999 | G12: =IF(A12<=(Part2!$C$17/Part2!$D$17),1,((Part2!$C$17/Part2!$D$17)^A12/FACT(A12)*A12/(A12-(Part2!$C$17/Part2!$D$17)))/(SUMPRODUCT(($L$3:$L$102<A12)*((Part2!$C$17/Part2!$D$17)^$L$3:$L$102/FACT($L$3:$L$102)))+((Part2!$C$17/Part2!$D$17)^A12/FACT(A12)*A12/(A12-(Part2!$C$17/Part2!$D$17))))) -> 1 | H12: =IF(I12<=Part2!$G$9,A12,9999) -> 9999 | I12: =IF(A12<=(Part2!$C$18/Part2!$D$18),9999,J12/(A12*Part2!$D$18-Part2!$C$18)*60) -> 9999 | J12: =IF(A12<=(Part2!$C$18/Part2!$D$18),1,((Part2!$C$18/Part2!$D$18)^A12/FACT(A12)*A12/(A12-(Part2!$C$18/Part2!$D$18)))/(SUMPRODUCT(($L$3:$L$102<A12)*((Part2!$C$18/Part2!$D$18)^$L$3:$L$102/FACT($L$3:$L$102)))+((Part2!$C$18/Part2!$D$18)^A12/FACT(A12)*A12/(A12-(Part2!$C$18/Part2!$D$18))))) -> 1 | L12: 9
A13: 11 | B13: =IF(C13<=Part2!$G$5,A13,9999) -> 9999 | C13: =IF(A13<=(Part2!$C$16/Part2!$D$16),9999,D13/(A13*Part2!$D$16-Part2!$C$16)*60) -> 9999 | D13: =IF(A13<=(Part2!$C$16/Part2!$D$16),1,((Part2!$C$16/Part2!$D$16)^A13/FACT(A13)*A13/(A13-(Part2!$C$16/Part2!$D$16)))/(SUMPRODUCT(($L$3:$L$102<A13)*((Part2!$C$16/Part2!$D$16)^$L$3:$L$102/FACT($L$3:$L$102)))+((Part2!$C$16/Part2!$D$16)^A13/FACT(A13)*A13/(A13-(Part2!$C$16/Part2!$D$16))))) -> 1 | E13: =IF(F13<=Part2!$G$7,A13,9999) -> 9999 | F13: =IF(A13<=(Part2!$C$17/Part2!$D$17),9999,G13/(A13*Part2!$D$17-Part2!$C$17)*60) -> 9999 | G13: =IF(A13<=(Part2!$C$17/Part2!$D$17),1,((Part2!$C$17/Part2!$D$17)^A13/FACT(A13)*A13/(A13-(Part2!$C$17/Part2!$D$17)))/(SUMPRODUCT(($L$3:$L$102<A13)*((Part2!$C$17/Part2!$D$17)^$L$3:$L$102/FACT($L$3:$L$102)))+((Part2!$C$17/Part2!$D$17)^A13/FACT(A13)*A13/(A13-(Part2!$C$17/Part2!$D$17))))) -> 1 | H13: =IF(I13<=Part2!$G$9,A13,9999) -> 9999 | I13: =IF(A13<=(Part2!$C$18/Part2!$D$18),9999,J13/(A13*Part2!$D$18-Part2!$C$18)*60) -> 9999 | J13: =IF(A13<=(Part2!$C$18/Part2!$D$18),1,((Part2!$C$18/Part2!$D$18)^A13/FACT(A13)*A13/(A13-(Part2!$C$18/Part2!$D$18)))/(SUMPRODUCT(($L$3:$L$102<A13)*((Part2!$C$18/Part2!$D$18)^$L$3:$L$102/FACT($L$3:$L$102)))+((Part2!$C$18/Part2!$D$18)^A13/FACT(A13)*A13/(A13-(Part2!$C$18/Part2!$D$18))))) -> 1 | L13: 10
A14: 12 | B14: =IF(C14<=Part2!$G$5,A14,9999) -> 9999 | C14: =IF(A14<=(Part2!$C$16/Part2!$D$16),9999,D14/(A14*Part2!$D$16-Part2!$C$16)*60) -> 9999 | D14: =IF(A14<=(Part2!$C$16/Part2!$D$16),1,((Part2!$C$16/Part2!$D$16)^A14/FACT(A14)*A14/(A14-(Part2!$C$16/Part2!$D$16)))/(SUMPRODUCT(($L$3:$L$102<A14)*((Part2!$C$16/Part2!$D$16)^$L$3:$L$102/FACT($L$3:$L$102)))+((Part2!$C$16/Part2!$D$16)^A14/FACT(A14)*A14/(A14-(Part2!$C$16/Part2!$D$16))))) -> 1 | E14: =IF(F14<=Part2!$G$7,A14,9999) -> 9999 | F14: =IF(A14<=(Part2!$C$17/Part2!$D$17),9999,G14/(A14*Part2!$D$17-Part2!$C$17)*60) -> 9999 | G14: =IF(A14<=(Part2!$C$17/Part2!$D$17),1,((Part2!$C$17/Part2!$D$17)^A14/FACT(A14)*A14/(A14-(Part2!$C$17/Part2!$D$17)))/(SUMPRODUCT(($L$3:$L$102<A14)*((Part2!$C$17/Part2!$D$17)^$L$3:$L$102/FACT($L$3:$L$102)))+((Part2!$C$17/Part2!$D$17)^A14/FACT(A14)*A14/(A14-(Part2!$C$17/Part2!$D$17))))) -> 1 | H14: =IF(I14<=Part2!$G$9,A14,9999) -> 9999 | I14: =IF(A14<=(Part2!$C$18/Part2!$D$18),9999,J14/(A14*Part2!$D$18-Part2!$C$18)*60) -> 9999 | J14: =IF(A14<=(Part2!$C$18/Part2!$D$18),1,((Part2!$C$18/Part2!$D$18)^A14/FACT(A14)*A14/(A14-(Part2!$C$18/Part2!$D$18)))/(SUMPRODUCT(($L$3:$L$102<A14)*((Part2!$C$18/Part2!$D$18)^$L$3:$L$102/FACT($L$3:$L$102)))+((Part2!$C$18/Part2!$D$18)^A14/FACT(A14)*A14/(A14-(Part2!$C$18/Part2!$D$18))))) -> 1 | L14: 11
... A102: 100 | B102: =IF(C102<=Part2!$G$5,A102,9999) -> 100 | C102: =IF(A102<=(Part2!$C$16/Part2!$D$16),9999,D102/(A102*Part2!$D$16-Part2!$C$16)*60) -> 2.6785631e-13 | D102: =IF(A102<=(Part2!$C$16/Part2!$D$16),1,((Part2!$C$16/Part2!$D$16)^A102/FACT(A102)*A102/(A102-(Part2!$C$16/Part2!$D$16)))/(SUMPRODUCT(($L$3:$L$102<A102)*((Part2!$C$16/Part2!$D$16)^$L$3:$L$102/FACT($L$3:$L$102)))+((Part2!$C$16/Part2!$D$16)^A102/FACT(A102)*A102/(A102-(Part2!$C$16/Part2!$D$16))))) -> 1.1377561e-11 | E102: =IF(F102<=Part2!$G$7,A102,9999) -> 100 | F102: =IF(A102<=(Part2!$C$17/Part2!$D$17),9999,G102/(A102*Part2!$D$17-Part2!$C$17)*60) -> 1.7584156e-28 | G102: =IF(A102<=(Part2!$C$17/Part2!$D$17),1,((Part2!$C$17/Part2!$D$17)^A102/FACT(A102)*A102/(A102-(Part2!$C$17/Part2!$D$17)))/(SUMPRODUCT(($L$3:$L$102<A102)*((Part2!$C$17/Part2!$D$17)^$L$3:$L$102/FACT($L$3:$L$102)))+((Part2!$C$17/Part2!$D$17)^A102/FACT(A102)*A102/(A102-(Part2!$C$17/Part2!$D$17))))) -> 4.2761287e-27 | H102: =IF(I102<=Part2!$G$9,A102,9999) -> 100 | I102: =IF(A102<=(Part2!$C$18/Part2!$D$18),9999,J102/(A102*Part2!$D$18-Part2!$C$18)*60) -> 1.6891884e-54 | J102: =IF(A102<=(Part2!$C$18/Part2!$D$18),1,((Part2!$C$18/Part2!$D$18)^A102/FACT(A102)*A102/(A102-(Part2!$C$18/Part2!$D$18)))/(SUMPRODUCT(($L$3:$L$102<A102)*((Part2!$C$18/Part2!$D$18)^$L$3:$L$102/FACT($L$3:$L$102)))+((Part2!$C$18/Part2!$D$18)^A102/FACT(A102)*A102/(A102-(Part2!$C$18/Part2!$D$18))))) -> 1.4676834e-52 | L102: 99
A104: P(wait) = [a^c/c! * c/(c-a)] / [sum_{k<c} a^k/k! + a^c/c! * c/(c-a)]; Wq = P(wait) / (c*mu - lambda). Floor = smallest c with Wq under the target.

Sheet Part3
A1: Organizer revenue per guest
A2: Admission $ | B2: 12
A3: Parking $ per guest | B3: 1.5
A4: Revenue share on spend $ | B4: =(Part2!C4*Part2!D4*Part2!B4*Part2!G4+Part2!C6*Part2!D6*Part2!B6*Part2!G6+Part2!C8*Part2!D8*Part2!B8*Part2!G8)*Part2!B12 -> 3.959808
A5: Revenue per guest $ | B5: =B2+B3+B4 -> 17.459808
A7: Cost inputs (team assumptions; replace with the festival's actuals)
A8: Staff on site | B8: 50
A9: Wage $/hr | B9: 22
A10: Cost escalator (2027) | B10: =Escalator -> 0.046
A11: Lighting and security per extended day $ | B11: 2500
A12: Operations per added day $ | B12: 8000
A13: Extra site week $ | B13: 20000
A14: Launch marketing, Fridays $ | B14: 10000
A15: Launch marketing, fifth weekend $ | B15: 8000
A17: Demand assumptions
A18: Season attendance | B18: =Part2!B10 -> 62100
A19: Average Saturday | B19: =B18*SatShare/4 -> 8538.75
A20: Average weekend | B20: =B18/4 -> 15525
A21: Average demand per operating hour | B21: =B18/80 -> 776.25
A22: A: share of arrivals in the two added hours | B22: 0.07
A23: A: redistribution (pulled from open hours) | B23: 0.6
A24: B: Friday as a share of Saturday | B24: 0.45
A25: B: redistribution from the weekend | B25: 0.35
A26: C: fifth weekend vs average weekend | B26: 0.65
A27: C: redistribution | B27: 0.4
A29: Option economics
A30: Option | B30: Hours added | C30: Gross demand | D30: Net new | E30: Net new % | F30: Revenue $ | G30: Cost $ | H30: Net $ | I30: Capacity factor | J30: Peak relief (shifted visits)
A31: A. Extend to 12 hours | B31: 16 | C31: =B18*B22 -> 4347 | D31: =C31*(1-B23) -> 1738.8 | E31: =D31/$B$18 -> 0.028 | F31: =D31*$B$5 -> 30359.114 | G31: =B8*B9*(1+B10)*2*8+B11*8 -> 38409.6 | H31: =F31-G31 -> -8050.4858 | I31: =C31/(B31*$B$21) -> 0.35 | J31: =C31-D31 -> 2608.2
A32: B. Add Fridays | B32: 40 | C32: =4*B24*B19 -> 15369.75 | D32: =C32*(1-B25) -> 9990.3375 | E32: =D32/$B$18 -> 0.160875 | F32: =D32*$B$5 -> 174429.37 | G32: =B8*B9*(1+B10)*11*4+B12*4+B14 -> 92626.4 | H32: =F32-G32 -> 81802.975 | I32: =C32/(B32*$B$21) -> 0.495 | J32: =C32-D32 -> 5379.4125
A33: C. Fifth weekend | B33: 20 | C33: =B26*B20 -> 10091.25 | D33: =C33*(1-B27) -> 6054.75 | E33: =D33/$B$18 -> 0.0975 | F33: =D33*$B$5 -> 105714.77 | G33: =B8*B9*(1+B10)*11*2+B12*2+B13+B15 -> 69313.2 | H33: =F33-G33 -> 36401.572 | I33: =C33/(B33*$B$21) -> 0.65 | J33: =C33-D33 -> 4036.5
A36: Weighted scorecard (1 to 5)
A37: Option | B37: Financial (35%) | C37: Guest experience (30%) | D37: Feasibility (20%) | E37: Risk (15%) | F37: Weighted score
A38: A. Extend hours | B38: 1 | C38: 2 | D38: 4 | E38: 3 | F38: =0.35*B38+0.3*C38+0.2*D38+0.15*E38 -> 2.2
A39: B. Add Fridays | B39: 5 | C39: 4 | D39: 3 | E39: 3 | F39: =0.35*B39+0.3*C39+0.2*D39+0.15*E39 -> 4
A40: C. Fifth weekend | B40: 3 | C40: 3 | D40: 4 | E40: 2 | F40: =0.35*B40+0.3*C40+0.2*D40+0.15*E40 -> 3.05
A42: 2029 design day without new capacity | B42: =(B18+3*1500+Capture!E32)*WkS3*SatShare -> 12058.658 | C42: Trend 1,500 a year plus the outer-ring ramp from the Capture sheet
